
Exception caught at 2021-10-08 15:30:33.559331:
Traceback (most recent call last):
  File "internal/testpy/test_framework.py", line 238, in <module>
    main()
  File "internal/testpy/test_framework.py", line 46, in main
    input("Press Enter to Exit...")
EOFError

Exception caught at 2021-10-29 16:14:06.275522:
Traceback (most recent call last):
  File "internal/testpy/test_framework.py", line 238, in <module>
    main()
  File "internal/testpy/test_framework.py", line 57, in main
    input("Press Enter To Exit...")
EOFError
