
Exception caught at 2021-10-08 15:30:33.559331:
Traceback (most recent call last):
  File "internal/testpy/test_framework.py", line 238, in <module>
    main()
  File "internal/testpy/test_framework.py", line 46, in main
    input("Press Enter to Exit...")
EOFError

Exception caught at 2021-10-29 16:14:06.275522:
Traceback (most recent call last):
  File "internal/testpy/test_framework.py", line 238, in <module>
    main()
  File "internal/testpy/test_framework.py", line 57, in main
    input("Press Enter To Exit...")
EOFError

Exception caught at 2021-10-29 16:23:18.842204:
Traceback (most recent call last):
  File "internal/testpy/test_framework.py", line 238, in <module>
    main()
  File "internal/testpy/test_framework.py", line 57, in main
    input("Press Enter To Exit...")
EOFError

Exception caught at 2021-11-03 18:18:28.477160:
Traceback (most recent call last):
  File "internal/testpy/test_framework.py", line 238, in <module>
    main()
  File "internal/testpy/test_framework.py", line 57, in main
    input("Press Enter To Exit...")
EOFError

Exception caught at 2021-11-03 18:18:28.476897:
Traceback (most recent call last):
  File "internal/testpy/test_framework.py", line 238, in <module>
    main()
  File "internal/testpy/test_framework.py", line 57, in main
    input("Press Enter To Exit...")
EOFError

Exception caught at 2021-11-04 23:32:35.357803:
Traceback (most recent call last):
  File "/usr/local/mentor/calibre/pkgs/icv_python/asp/lib/python3.6/tkinter/__init__.py", line 1702, in __call__
    return self.func(*args)
  File "/home/bkfergen/Desktop/CPRE-381-Team-Project-1/internal/testpy/run_gui.py", line 197, in chooseSelectedFiles
    test_framework.queueSimulation(asm_files_to_run, options)
  File "/home/bkfergen/Desktop/CPRE-381-Team-Project-1/internal/testpy/test_framework.py", line 65, in queueSimulation
    runSimulation(x,simOptions)
  File "/home/bkfergen/Desktop/CPRE-381-Team-Project-1/internal/testpy/test_framework.py", line 72, in runSimulation
    options['asm-path'] = mars.run_sim(asm_file=asm_Path)
  File "/home/bkfergen/Desktop/CPRE-381-Team-Project-1/internal/testpy/mars.py", line 72, in run_sim
    return run_sim()
  File "/home/bkfergen/Desktop/CPRE-381-Team-Project-1/internal/testpy/mars.py", line 45, in run_sim
    path = input('>').strip()
EOFError

During handling of the above exception, another exception occurred:

Traceback (most recent call last):
  File "internal/testpy/test_framework.py", line 238, in <module>
    main()
  File "internal/testpy/test_framework.py", line 55, in main
    run_gui.guiMain()
  File "/home/bkfergen/Desktop/CPRE-381-Team-Project-1/internal/testpy/run_gui.py", line 156, in guiMain
    window.mainloop()
  File "/usr/local/mentor/calibre/pkgs/icv_python/asp/lib/python3.6/tkinter/__init__.py", line 1280, in mainloop
    self.tk.mainloop(n)
  File "/usr/local/mentor/calibre/pkgs/icv_python/asp/lib/python3.6/tkinter/__init__.py", line 1706, in __call__
    self.widget._report_exception()
  File "/usr/local/mentor/calibre/pkgs/icv_python/asp/lib/python3.6/tkinter/__init__.py", line 1449, in _report_exception
    root.report_callback_exception(exc, val, tb)
  File "/usr/local/mentor/calibre/pkgs/icv_python/asp/lib/python3.6/tkinter/__init__.py", line 2091, in report_callback_exception
    print("Exception in Tkinter callback", file=sys.stderr)
OSError: [Errno 5] Input/output error

Exception caught at 2021-11-05 14:18:31.380401:
Traceback (most recent call last):
  File "/usr/local/mentor/calibre/pkgs/icv_python/asp/lib/python3.6/tkinter/__init__.py", line 1702, in __call__
    return self.func(*args)
  File "/home/bkfergen/Desktop/CPRE-381-Team-Project-1/internal/testpy/run_gui.py", line 197, in chooseSelectedFiles
    test_framework.queueSimulation(asm_files_to_run, options)
  File "/home/bkfergen/Desktop/CPRE-381-Team-Project-1/internal/testpy/test_framework.py", line 65, in queueSimulation
    runSimulation(x,simOptions)
  File "/home/bkfergen/Desktop/CPRE-381-Team-Project-1/internal/testpy/test_framework.py", line 72, in runSimulation
    options['asm-path'] = mars.run_sim(asm_file=asm_Path)
  File "/home/bkfergen/Desktop/CPRE-381-Team-Project-1/internal/testpy/mars.py", line 72, in run_sim
    return run_sim()
  File "/home/bkfergen/Desktop/CPRE-381-Team-Project-1/internal/testpy/mars.py", line 45, in run_sim
    path = input('>').strip()
EOFError

During handling of the above exception, another exception occurred:

Traceback (most recent call last):
  File "internal/testpy/test_framework.py", line 238, in <module>
    main()
  File "internal/testpy/test_framework.py", line 55, in main
    run_gui.guiMain()
  File "/home/bkfergen/Desktop/CPRE-381-Team-Project-1/internal/testpy/run_gui.py", line 156, in guiMain
    window.mainloop()
  File "/usr/local/mentor/calibre/pkgs/icv_python/asp/lib/python3.6/tkinter/__init__.py", line 1280, in mainloop
    self.tk.mainloop(n)
  File "/usr/local/mentor/calibre/pkgs/icv_python/asp/lib/python3.6/tkinter/__init__.py", line 1706, in __call__
    self.widget._report_exception()
  File "/usr/local/mentor/calibre/pkgs/icv_python/asp/lib/python3.6/tkinter/__init__.py", line 1449, in _report_exception
    root.report_callback_exception(exc, val, tb)
  File "/usr/local/mentor/calibre/pkgs/icv_python/asp/lib/python3.6/tkinter/__init__.py", line 2091, in report_callback_exception
    print("Exception in Tkinter callback", file=sys.stderr)
OSError: [Errno 5] Input/output error
